[2024-06-21T01:11:23.197+0000] {local_task_job_runner.py:120} INFO - ::group::Pre task execution logs
[2024-06-21T01:11:23.224+0000] {taskinstance.py:2076} INFO - Dependencies all met for dep_context=non-requeueable deps ti=<TaskInstance: pokemons.getpokemons manual__2024-06-21T01:11:21.730001+00:00 [queued]>
[2024-06-21T01:11:23.233+0000] {taskinstance.py:2076} INFO - Dependencies all met for dep_context=requeueable deps ti=<TaskInstance: pokemons.getpokemons manual__2024-06-21T01:11:21.730001+00:00 [queued]>
[2024-06-21T01:11:23.233+0000] {taskinstance.py:2306} INFO - Starting attempt 1 of 1
[2024-06-21T01:11:23.249+0000] {taskinstance.py:2330} INFO - Executing <Task(_PythonVirtualenvDecoratedOperator): getpokemons> on 2024-06-21 01:11:21.730001+00:00
[2024-06-21T01:11:23.256+0000] {warnings.py:110} WARNING - /home/***/.local/lib/python3.12/site-packages/***/task/task_runner/standard_task_runner.py:61: DeprecationWarning: This process (pid=568) is multi-threaded, use of fork() may lead to deadlocks in the child.
  pid = os.fork()

[2024-06-21T01:11:23.257+0000] {standard_task_runner.py:63} INFO - Started process 569 to run task
[2024-06-21T01:11:23.257+0000] {standard_task_runner.py:90} INFO - Running: ['***', 'tasks', 'run', 'pokemons', 'getpokemons', 'manual__2024-06-21T01:11:21.730001+00:00', '--job-id', '56', '--raw', '--subdir', 'DAGS_FOLDER/python_operators.py', '--cfg-path', '/tmp/tmpgpzk094_']
[2024-06-21T01:11:23.258+0000] {standard_task_runner.py:91} INFO - Job 56: Subtask getpokemons
[2024-06-21T01:11:23.302+0000] {task_command.py:426} INFO - Running <TaskInstance: pokemons.getpokemons manual__2024-06-21T01:11:21.730001+00:00 [running]> on host f9f27b1b4edb
[2024-06-21T01:11:23.387+0000] {taskinstance.py:2648} INFO - Exporting env vars: AIRFLOW_CTX_DAG_OWNER='***' AIRFLOW_CTX_DAG_ID='pokemons' AIRFLOW_CTX_TASK_ID='getpokemons' AIRFLOW_CTX_EXECUTION_DATE='2024-06-21T01:11:21.730001+00:00' AIRFLOW_CTX_TRY_NUMBER='1' AIRFLOW_CTX_DAG_RUN_ID='manual__2024-06-21T01:11:21.730001+00:00'
[2024-06-21T01:11:23.388+0000] {taskinstance.py:430} INFO - ::endgroup::
[2024-06-21T01:11:23.389+0000] {process_utils.py:183} INFO - Executing cmd: /home/***/.local/bin/python -m virtualenv /tmp/venv9il1zabz --system-site-packages --python=python
[2024-06-21T01:11:23.390+0000] {process_utils.py:187} INFO - Output:
[2024-06-21T01:11:24.196+0000] {process_utils.py:191} INFO - created virtual environment CPython3.12.3.final.0-64 in 227ms
[2024-06-21T01:11:24.196+0000] {process_utils.py:191} INFO -   creator CPython3Posix(dest=/tmp/venv9il1zabz, clear=False, no_vcs_ignore=False, global=True)
[2024-06-21T01:11:24.196+0000] {process_utils.py:191} INFO -   seeder FromAppData(download=False, pip=bundle, via=copy, app_data_dir=/home/***/.local/share/virtualenv)
[2024-06-21T01:11:24.197+0000] {process_utils.py:191} INFO -     added seed packages: pip==24.0
[2024-06-21T01:11:24.197+0000] {process_utils.py:191} INFO -   activators BashActivator,CShellActivator,FishActivator,NushellActivator,PowerShellActivator,PythonActivator
[2024-06-21T01:11:24.219+0000] {process_utils.py:183} INFO - Executing cmd: /tmp/venv9il1zabz/bin/pip install -r /tmp/venv9il1zabz/requirements.txt
[2024-06-21T01:11:24.220+0000] {process_utils.py:187} INFO - Output:
[2024-06-21T01:11:26.227+0000] {process_utils.py:191} INFO - Requirement already satisfied: requests in /home/***/.local/lib/python3.12/site-packages (from -r /tmp/venv9il1zabz/requirements.txt (line 1)) (2.31.0)
[2024-06-21T01:11:26.237+0000] {process_utils.py:191} INFO - Requirement already satisfied: charset-normalizer<4,>=2 in /home/***/.local/lib/python3.12/site-packages (from requests->-r /tmp/venv9il1zabz/requirements.txt (line 1)) (3.3.2)
[2024-06-21T01:11:26.238+0000] {process_utils.py:191} INFO - Requirement already satisfied: idna<4,>=2.5 in /home/***/.local/lib/python3.12/site-packages (from requests->-r /tmp/venv9il1zabz/requirements.txt (line 1)) (3.7)
[2024-06-21T01:11:26.240+0000] {process_utils.py:191} INFO - Requirement already satisfied: urllib3<3,>=1.21.1 in /home/***/.local/lib/python3.12/site-packages (from requests->-r /tmp/venv9il1zabz/requirements.txt (line 1)) (2.2.1)
[2024-06-21T01:11:26.241+0000] {process_utils.py:191} INFO - Requirement already satisfied: certifi>=2017.4.17 in /home/***/.local/lib/python3.12/site-packages (from requests->-r /tmp/venv9il1zabz/requirements.txt (line 1)) (2024.2.2)
[2024-06-21T01:11:29.211+0000] {process_utils.py:191} INFO - 
[2024-06-21T01:11:29.212+0000] {process_utils.py:191} INFO - [notice] A new release of pip is available: 24.0 -> 24.1
[2024-06-21T01:11:29.212+0000] {process_utils.py:191} INFO - [notice] To update, run: python -m pip install --upgrade pip
[2024-06-21T01:11:29.335+0000] {process_utils.py:183} INFO - Executing cmd: /tmp/venv9il1zabz/bin/python /tmp/venv-call3dp4k30z/script.py /tmp/venv-call3dp4k30z/script.in /tmp/venv-call3dp4k30z/script.out /tmp/venv-call3dp4k30z/string_args.txt /tmp/venv-call3dp4k30z/termination.log
[2024-06-21T01:11:29.336+0000] {process_utils.py:187} INFO - Output:
[2024-06-21T01:11:31.594+0000] {process_utils.py:191} INFO - getting: https://pokeapi.co/api/v2/pokemon/?offset=0&limit=0
[2024-06-21T01:11:31.594+0000] {process_utils.py:191} INFO - Traceback (most recent call last):
[2024-06-21T01:11:31.594+0000] {process_utils.py:191} INFO -   File "/tmp/venv-call3dp4k30z/script.py", line 55, in <module>
[2024-06-21T01:11:31.595+0000] {process_utils.py:191} INFO -     res = getpokemons(*arg_dict["args"], **arg_dict["kwargs"])
[2024-06-21T01:11:31.595+0000] {process_utils.py:191} INFO -           ^^^^^^^^^^^^^^^^^^^^^^^^^^^^^^^^^^^^^^^^^^^^^^^^^^^^
[2024-06-21T01:11:31.595+0000] {process_utils.py:191} INFO -   File "/tmp/venv-call3dp4k30z/script.py", line 26, in getpokemons
[2024-06-21T01:11:31.595+0000] {process_utils.py:191} INFO -     time.sleep(.5)
[2024-06-21T01:11:31.596+0000] {process_utils.py:191} INFO -     ^^^^
[2024-06-21T01:11:31.596+0000] {process_utils.py:191} INFO - NameError: name 'time' is not defined. Did you forget to import 'time'?
[2024-06-21T01:11:31.871+0000] {taskinstance.py:441} INFO - ::group::Post task execution logs
[2024-06-21T01:11:31.879+0000] {taskinstance.py:2905} ERROR - Task failed with exception
Traceback (most recent call last):
  File "/home/airflow/.local/lib/python3.12/site-packages/airflow/models/taskinstance.py", line 465, in _execute_task
    result = _execute_callable(context=context, **execute_callable_kwargs)
             ^^^^^^^^^^^^^^^^^^^^^^^^^^^^^^^^^^^^^^^^^^^^^^^^^^^^^^^^^^^^^
  File "/home/airflow/.local/lib/python3.12/site-packages/airflow/models/taskinstance.py", line 432, in _execute_callable
    return execute_callable(context=context, **execute_callable_kwargs)
           ^^^^^^^^^^^^^^^^^^^^^^^^^^^^^^^^^^^^^^^^^^^^^^^^^^^^^^^^^^^^
  File "/home/airflow/.local/lib/python3.12/site-packages/airflow/models/baseoperator.py", line 400, in wrapper
    return func(self, *args, **kwargs)
           ^^^^^^^^^^^^^^^^^^^^^^^^^^^
  File "/home/airflow/.local/lib/python3.12/site-packages/airflow/decorators/base.py", line 265, in execute
    return_value = super().execute(context)
                   ^^^^^^^^^^^^^^^^^^^^^^^^
  File "/home/airflow/.local/lib/python3.12/site-packages/airflow/models/baseoperator.py", line 400, in wrapper
    return func(self, *args, **kwargs)
           ^^^^^^^^^^^^^^^^^^^^^^^^^^^
  File "/home/airflow/.local/lib/python3.12/site-packages/airflow/operators/python.py", line 437, in execute
    return super().execute(context=serializable_context)
           ^^^^^^^^^^^^^^^^^^^^^^^^^^^^^^^^^^^^^^^^^^^^^
  File "/home/airflow/.local/lib/python3.12/site-packages/airflow/models/baseoperator.py", line 400, in wrapper
    return func(self, *args, **kwargs)
           ^^^^^^^^^^^^^^^^^^^^^^^^^^^
  File "/home/airflow/.local/lib/python3.12/site-packages/airflow/operators/python.py", line 235, in execute
    return_value = self.execute_callable()
                   ^^^^^^^^^^^^^^^^^^^^^^^
  File "/home/airflow/.local/lib/python3.12/site-packages/airflow/operators/python.py", line 759, in execute_callable
    result = self._execute_python_callable_in_subprocess(python_path)
             ^^^^^^^^^^^^^^^^^^^^^^^^^^^^^^^^^^^^^^^^^^^^^^^^^^^^^^^^
  File "/home/airflow/.local/lib/python3.12/site-packages/airflow/operators/python.py", line 514, in _execute_python_callable_in_subprocess
    raise AirflowException(error_msg) from None
airflow.exceptions.AirflowException: Process returned non-zero exit status 1.
name 'time' is not defined
[2024-06-21T01:11:31.883+0000] {taskinstance.py:1206} INFO - Marking task as FAILED. dag_id=pokemons, task_id=getpokemons, run_id=manual__2024-06-21T01:11:21.730001+00:00, execution_date=20240621T011121, start_date=20240621T011123, end_date=20240621T011131
[2024-06-21T01:11:31.906+0000] {standard_task_runner.py:110} ERROR - Failed to execute job 56 for task getpokemons (Process returned non-zero exit status 1.
name 'time' is not defined; 569)
[2024-06-21T01:11:31.930+0000] {local_task_job_runner.py:240} INFO - Task exited with return code 1
[2024-06-21T01:11:31.952+0000] {taskinstance.py:3498} INFO - 0 downstream tasks scheduled from follow-on schedule check
[2024-06-21T01:11:31.957+0000] {local_task_job_runner.py:222} INFO - ::endgroup::
