[2024-06-21T01:15:41.887+0000] {local_task_job_runner.py:120} INFO - ::group::Pre task execution logs
[2024-06-21T01:15:41.910+0000] {taskinstance.py:2076} INFO - Dependencies all met for dep_context=non-requeueable deps ti=<TaskInstance: pokemons.getpokemons manual__2024-06-21T01:15:39.597977+00:00 [queued]>
[2024-06-21T01:15:41.918+0000] {taskinstance.py:2076} INFO - Dependencies all met for dep_context=requeueable deps ti=<TaskInstance: pokemons.getpokemons manual__2024-06-21T01:15:39.597977+00:00 [queued]>
[2024-06-21T01:15:41.918+0000] {taskinstance.py:2306} INFO - Starting attempt 1 of 1
[2024-06-21T01:15:41.934+0000] {taskinstance.py:2330} INFO - Executing <Task(_PythonVirtualenvDecoratedOperator): getpokemons> on 2024-06-21 01:15:39.597977+00:00
[2024-06-21T01:15:41.942+0000] {warnings.py:110} WARNING - /home/***/.local/lib/python3.12/site-packages/***/task/task_runner/standard_task_runner.py:61: DeprecationWarning: This process (pid=73) is multi-threaded, use of fork() may lead to deadlocks in the child.
  pid = os.fork()

[2024-06-21T01:15:41.944+0000] {standard_task_runner.py:63} INFO - Started process 74 to run task
[2024-06-21T01:15:41.944+0000] {standard_task_runner.py:90} INFO - Running: ['***', 'tasks', 'run', 'pokemons', 'getpokemons', 'manual__2024-06-21T01:15:39.597977+00:00', '--job-id', '61', '--raw', '--subdir', 'DAGS_FOLDER/python_operators.py', '--cfg-path', '/tmp/tmph0eu14ml']
[2024-06-21T01:15:41.945+0000] {standard_task_runner.py:91} INFO - Job 61: Subtask getpokemons
[2024-06-21T01:15:41.988+0000] {task_command.py:426} INFO - Running <TaskInstance: pokemons.getpokemons manual__2024-06-21T01:15:39.597977+00:00 [running]> on host c357804a93ab
[2024-06-21T01:15:42.080+0000] {taskinstance.py:2648} INFO - Exporting env vars: AIRFLOW_CTX_DAG_OWNER='***' AIRFLOW_CTX_DAG_ID='pokemons' AIRFLOW_CTX_TASK_ID='getpokemons' AIRFLOW_CTX_EXECUTION_DATE='2024-06-21T01:15:39.597977+00:00' AIRFLOW_CTX_TRY_NUMBER='1' AIRFLOW_CTX_DAG_RUN_ID='manual__2024-06-21T01:15:39.597977+00:00'
[2024-06-21T01:15:42.080+0000] {taskinstance.py:430} INFO - ::endgroup::
[2024-06-21T01:15:42.082+0000] {process_utils.py:183} INFO - Executing cmd: /home/***/.local/bin/python -m virtualenv /tmp/venvtrposjwc --system-site-packages --python=python
[2024-06-21T01:15:42.082+0000] {process_utils.py:187} INFO - Output:
[2024-06-21T01:15:43.364+0000] {process_utils.py:191} INFO - created virtual environment CPython3.12.3.final.0-64 in 700ms
[2024-06-21T01:15:43.364+0000] {process_utils.py:191} INFO -   creator CPython3Posix(dest=/tmp/venvtrposjwc, clear=False, no_vcs_ignore=False, global=True)
[2024-06-21T01:15:43.365+0000] {process_utils.py:191} INFO -   seeder FromAppData(download=False, pip=bundle, via=copy, app_data_dir=/home/***/.local/share/virtualenv)
[2024-06-21T01:15:43.366+0000] {process_utils.py:191} INFO -     added seed packages: pip==24.0
[2024-06-21T01:15:43.366+0000] {process_utils.py:191} INFO -   activators BashActivator,CShellActivator,FishActivator,NushellActivator,PowerShellActivator,PythonActivator
[2024-06-21T01:15:43.405+0000] {process_utils.py:183} INFO - Executing cmd: /tmp/venvtrposjwc/bin/pip install -r /tmp/venvtrposjwc/requirements.txt
[2024-06-21T01:15:43.406+0000] {process_utils.py:187} INFO - Output:
[2024-06-21T01:15:45.748+0000] {process_utils.py:191} INFO - Requirement already satisfied: requests in /home/***/.local/lib/python3.12/site-packages (from -r /tmp/venvtrposjwc/requirements.txt (line 1)) (2.31.0)
[2024-06-21T01:15:45.762+0000] {process_utils.py:191} INFO - Requirement already satisfied: charset-normalizer<4,>=2 in /home/***/.local/lib/python3.12/site-packages (from requests->-r /tmp/venvtrposjwc/requirements.txt (line 1)) (3.3.2)
[2024-06-21T01:15:45.764+0000] {process_utils.py:191} INFO - Requirement already satisfied: idna<4,>=2.5 in /home/***/.local/lib/python3.12/site-packages (from requests->-r /tmp/venvtrposjwc/requirements.txt (line 1)) (3.7)
[2024-06-21T01:15:45.766+0000] {process_utils.py:191} INFO - Requirement already satisfied: urllib3<3,>=1.21.1 in /home/***/.local/lib/python3.12/site-packages (from requests->-r /tmp/venvtrposjwc/requirements.txt (line 1)) (2.2.1)
[2024-06-21T01:15:45.769+0000] {process_utils.py:191} INFO - Requirement already satisfied: certifi>=2017.4.17 in /home/***/.local/lib/python3.12/site-packages (from requests->-r /tmp/venvtrposjwc/requirements.txt (line 1)) (2024.2.2)
[2024-06-21T01:15:49.086+0000] {process_utils.py:191} INFO - 
[2024-06-21T01:15:49.087+0000] {process_utils.py:191} INFO - [notice] A new release of pip is available: 24.0 -> 24.1
[2024-06-21T01:15:49.087+0000] {process_utils.py:191} INFO - [notice] To update, run: python -m pip install --upgrade pip
[2024-06-21T01:15:49.196+0000] {process_utils.py:183} INFO - Executing cmd: /tmp/venvtrposjwc/bin/python /tmp/venv-callyfxwvpge/script.py /tmp/venv-callyfxwvpge/script.in /tmp/venv-callyfxwvpge/script.out /tmp/venv-callyfxwvpge/string_args.txt /tmp/venv-callyfxwvpge/termination.log
[2024-06-21T01:15:49.197+0000] {process_utils.py:187} INFO - Output:
[2024-06-21T01:15:51.534+0000] {process_utils.py:191} INFO - getting: https://pokeapi.co/api/v2/pokemon/?offset=0&limit=0
[2024-06-21T01:15:51.535+0000] {process_utils.py:191} INFO - Traceback (most recent call last):
[2024-06-21T01:15:51.535+0000] {process_utils.py:191} INFO -   File "/tmp/venv-callyfxwvpge/script.py", line 55, in <module>
[2024-06-21T01:15:51.535+0000] {process_utils.py:191} INFO -     res = getpokemons(*arg_dict["args"], **arg_dict["kwargs"])
[2024-06-21T01:15:51.535+0000] {process_utils.py:191} INFO -           ^^^^^^^^^^^^^^^^^^^^^^^^^^^^^^^^^^^^^^^^^^^^^^^^^^^^
[2024-06-21T01:15:51.536+0000] {process_utils.py:191} INFO -   File "/tmp/venv-callyfxwvpge/script.py", line 26, in getpokemons
[2024-06-21T01:15:51.536+0000] {process_utils.py:191} INFO -     time.sleep(.5)
[2024-06-21T01:15:51.536+0000] {process_utils.py:191} INFO -     ^^^^
[2024-06-21T01:15:51.536+0000] {process_utils.py:191} INFO - NameError: name 'time' is not defined. Did you forget to import 'time'?
[2024-06-21T01:15:51.758+0000] {taskinstance.py:441} INFO - ::group::Post task execution logs
[2024-06-21T01:15:51.767+0000] {taskinstance.py:2905} ERROR - Task failed with exception
Traceback (most recent call last):
  File "/home/airflow/.local/lib/python3.12/site-packages/airflow/models/taskinstance.py", line 465, in _execute_task
    result = _execute_callable(context=context, **execute_callable_kwargs)
             ^^^^^^^^^^^^^^^^^^^^^^^^^^^^^^^^^^^^^^^^^^^^^^^^^^^^^^^^^^^^^
  File "/home/airflow/.local/lib/python3.12/site-packages/airflow/models/taskinstance.py", line 432, in _execute_callable
    return execute_callable(context=context, **execute_callable_kwargs)
           ^^^^^^^^^^^^^^^^^^^^^^^^^^^^^^^^^^^^^^^^^^^^^^^^^^^^^^^^^^^^
  File "/home/airflow/.local/lib/python3.12/site-packages/airflow/models/baseoperator.py", line 400, in wrapper
    return func(self, *args, **kwargs)
           ^^^^^^^^^^^^^^^^^^^^^^^^^^^
  File "/home/airflow/.local/lib/python3.12/site-packages/airflow/decorators/base.py", line 265, in execute
    return_value = super().execute(context)
                   ^^^^^^^^^^^^^^^^^^^^^^^^
  File "/home/airflow/.local/lib/python3.12/site-packages/airflow/models/baseoperator.py", line 400, in wrapper
    return func(self, *args, **kwargs)
           ^^^^^^^^^^^^^^^^^^^^^^^^^^^
  File "/home/airflow/.local/lib/python3.12/site-packages/airflow/operators/python.py", line 437, in execute
    return super().execute(context=serializable_context)
           ^^^^^^^^^^^^^^^^^^^^^^^^^^^^^^^^^^^^^^^^^^^^^
  File "/home/airflow/.local/lib/python3.12/site-packages/airflow/models/baseoperator.py", line 400, in wrapper
    return func(self, *args, **kwargs)
           ^^^^^^^^^^^^^^^^^^^^^^^^^^^
  File "/home/airflow/.local/lib/python3.12/site-packages/airflow/operators/python.py", line 235, in execute
    return_value = self.execute_callable()
                   ^^^^^^^^^^^^^^^^^^^^^^^
  File "/home/airflow/.local/lib/python3.12/site-packages/airflow/operators/python.py", line 759, in execute_callable
    result = self._execute_python_callable_in_subprocess(python_path)
             ^^^^^^^^^^^^^^^^^^^^^^^^^^^^^^^^^^^^^^^^^^^^^^^^^^^^^^^^
  File "/home/airflow/.local/lib/python3.12/site-packages/airflow/operators/python.py", line 514, in _execute_python_callable_in_subprocess
    raise AirflowException(error_msg) from None
airflow.exceptions.AirflowException: Process returned non-zero exit status 1.
name 'time' is not defined
[2024-06-21T01:15:51.770+0000] {taskinstance.py:1206} INFO - Marking task as FAILED. dag_id=pokemons, task_id=getpokemons, run_id=manual__2024-06-21T01:15:39.597977+00:00, execution_date=20240621T011539, start_date=20240621T011541, end_date=20240621T011551
[2024-06-21T01:15:51.792+0000] {standard_task_runner.py:110} ERROR - Failed to execute job 61 for task getpokemons (Process returned non-zero exit status 1.
name 'time' is not defined; 74)
[2024-06-21T01:15:51.818+0000] {local_task_job_runner.py:240} INFO - Task exited with return code 1
[2024-06-21T01:15:51.875+0000] {taskinstance.py:3498} INFO - 0 downstream tasks scheduled from follow-on schedule check
[2024-06-21T01:15:51.881+0000] {local_task_job_runner.py:222} INFO - ::endgroup::
