[2024-06-23T00:04:15.245+0000] {task_context_logger.py:104} ERROR - Executor reports task instance <TaskInstance: pokemon_example.metricspokemonweights manual__2024-06-23T00:01:34.566508+00:00 [queued]> finished (failed) although the task says it's queued. (Info: None) Was the task killed externally?
