[2024-06-21T01:13:38.613+0000] {local_task_job_runner.py:120} INFO - ::group::Pre task execution logs
[2024-06-21T01:13:38.635+0000] {taskinstance.py:2076} INFO - Dependencies all met for dep_context=non-requeueable deps ti=<TaskInstance: pokemons.getpokemons manual__2024-06-21T01:13:37.153672+00:00 [queued]>
[2024-06-21T01:13:38.644+0000] {taskinstance.py:2076} INFO - Dependencies all met for dep_context=requeueable deps ti=<TaskInstance: pokemons.getpokemons manual__2024-06-21T01:13:37.153672+00:00 [queued]>
[2024-06-21T01:13:38.645+0000] {taskinstance.py:2306} INFO - Starting attempt 1 of 1
[2024-06-21T01:13:38.659+0000] {taskinstance.py:2330} INFO - Executing <Task(_PythonVirtualenvDecoratedOperator): getpokemons> on 2024-06-21 01:13:37.153672+00:00
[2024-06-21T01:13:38.666+0000] {warnings.py:110} WARNING - /home/***/.local/lib/python3.12/site-packages/***/task/task_runner/standard_task_runner.py:61: DeprecationWarning: This process (pid=655) is multi-threaded, use of fork() may lead to deadlocks in the child.
  pid = os.fork()

[2024-06-21T01:13:38.668+0000] {standard_task_runner.py:63} INFO - Started process 656 to run task
[2024-06-21T01:13:38.668+0000] {standard_task_runner.py:90} INFO - Running: ['***', 'tasks', 'run', 'pokemons', 'getpokemons', 'manual__2024-06-21T01:13:37.153672+00:00', '--job-id', '58', '--raw', '--subdir', 'DAGS_FOLDER/python_operators.py', '--cfg-path', '/tmp/tmpqxw9nxkp']
[2024-06-21T01:13:38.669+0000] {standard_task_runner.py:91} INFO - Job 58: Subtask getpokemons
[2024-06-21T01:13:38.712+0000] {task_command.py:426} INFO - Running <TaskInstance: pokemons.getpokemons manual__2024-06-21T01:13:37.153672+00:00 [running]> on host f9f27b1b4edb
[2024-06-21T01:13:38.797+0000] {taskinstance.py:2648} INFO - Exporting env vars: AIRFLOW_CTX_DAG_OWNER='***' AIRFLOW_CTX_DAG_ID='pokemons' AIRFLOW_CTX_TASK_ID='getpokemons' AIRFLOW_CTX_EXECUTION_DATE='2024-06-21T01:13:37.153672+00:00' AIRFLOW_CTX_TRY_NUMBER='1' AIRFLOW_CTX_DAG_RUN_ID='manual__2024-06-21T01:13:37.153672+00:00'
[2024-06-21T01:13:38.797+0000] {taskinstance.py:430} INFO - ::endgroup::
[2024-06-21T01:13:38.799+0000] {process_utils.py:183} INFO - Executing cmd: /home/***/.local/bin/python -m virtualenv /tmp/venvpcmzmgvz --system-site-packages --python=python
[2024-06-21T01:13:38.800+0000] {process_utils.py:187} INFO - Output:
[2024-06-21T01:13:39.650+0000] {process_utils.py:191} INFO - created virtual environment CPython3.12.3.final.0-64 in 249ms
[2024-06-21T01:13:39.650+0000] {process_utils.py:191} INFO -   creator CPython3Posix(dest=/tmp/venvpcmzmgvz, clear=False, no_vcs_ignore=False, global=True)
[2024-06-21T01:13:39.651+0000] {process_utils.py:191} INFO -   seeder FromAppData(download=False, pip=bundle, via=copy, app_data_dir=/home/***/.local/share/virtualenv)
[2024-06-21T01:13:39.651+0000] {process_utils.py:191} INFO -     added seed packages: pip==24.0
[2024-06-21T01:13:39.651+0000] {process_utils.py:191} INFO -   activators BashActivator,CShellActivator,FishActivator,NushellActivator,PowerShellActivator,PythonActivator
[2024-06-21T01:13:39.673+0000] {process_utils.py:183} INFO - Executing cmd: /tmp/venvpcmzmgvz/bin/pip install -r /tmp/venvpcmzmgvz/requirements.txt
[2024-06-21T01:13:39.674+0000] {process_utils.py:187} INFO - Output:
[2024-06-21T01:13:41.833+0000] {process_utils.py:191} INFO - Requirement already satisfied: requests in /home/***/.local/lib/python3.12/site-packages (from -r /tmp/venvpcmzmgvz/requirements.txt (line 1)) (2.31.0)
[2024-06-21T01:13:41.842+0000] {process_utils.py:191} INFO - Requirement already satisfied: charset-normalizer<4,>=2 in /home/***/.local/lib/python3.12/site-packages (from requests->-r /tmp/venvpcmzmgvz/requirements.txt (line 1)) (3.3.2)
[2024-06-21T01:13:41.844+0000] {process_utils.py:191} INFO - Requirement already satisfied: idna<4,>=2.5 in /home/***/.local/lib/python3.12/site-packages (from requests->-r /tmp/venvpcmzmgvz/requirements.txt (line 1)) (3.7)
[2024-06-21T01:13:41.846+0000] {process_utils.py:191} INFO - Requirement already satisfied: urllib3<3,>=1.21.1 in /home/***/.local/lib/python3.12/site-packages (from requests->-r /tmp/venvpcmzmgvz/requirements.txt (line 1)) (2.2.1)
[2024-06-21T01:13:41.847+0000] {process_utils.py:191} INFO - Requirement already satisfied: certifi>=2017.4.17 in /home/***/.local/lib/python3.12/site-packages (from requests->-r /tmp/venvpcmzmgvz/requirements.txt (line 1)) (2024.2.2)
[2024-06-21T01:13:44.853+0000] {process_utils.py:191} INFO - 
[2024-06-21T01:13:44.853+0000] {process_utils.py:191} INFO - [notice] A new release of pip is available: 24.0 -> 24.1
[2024-06-21T01:13:44.854+0000] {process_utils.py:191} INFO - [notice] To update, run: python -m pip install --upgrade pip
[2024-06-21T01:13:44.948+0000] {process_utils.py:183} INFO - Executing cmd: /tmp/venvpcmzmgvz/bin/python /tmp/venv-cally6kn49kv/script.py /tmp/venv-cally6kn49kv/script.in /tmp/venv-cally6kn49kv/script.out /tmp/venv-cally6kn49kv/string_args.txt /tmp/venv-cally6kn49kv/termination.log
[2024-06-21T01:13:44.948+0000] {process_utils.py:187} INFO - Output:
[2024-06-21T01:13:47.224+0000] {process_utils.py:191} INFO - getting: https://pokeapi.co/api/v2/pokemon/?offset=0&limit=0
[2024-06-21T01:13:47.225+0000] {process_utils.py:191} INFO - Traceback (most recent call last):
[2024-06-21T01:13:47.225+0000] {process_utils.py:191} INFO -   File "/tmp/venv-cally6kn49kv/script.py", line 55, in <module>
[2024-06-21T01:13:47.226+0000] {process_utils.py:191} INFO -     res = getpokemons(*arg_dict["args"], **arg_dict["kwargs"])
[2024-06-21T01:13:47.226+0000] {process_utils.py:191} INFO -           ^^^^^^^^^^^^^^^^^^^^^^^^^^^^^^^^^^^^^^^^^^^^^^^^^^^^
[2024-06-21T01:13:47.227+0000] {process_utils.py:191} INFO -   File "/tmp/venv-cally6kn49kv/script.py", line 26, in getpokemons
[2024-06-21T01:13:47.227+0000] {process_utils.py:191} INFO -     time.sleep(.5)
[2024-06-21T01:13:47.227+0000] {process_utils.py:191} INFO -     ^^^^
[2024-06-21T01:13:47.227+0000] {process_utils.py:191} INFO - NameError: name 'time' is not defined. Did you forget to import 'time'?
[2024-06-21T01:13:47.487+0000] {taskinstance.py:441} INFO - ::group::Post task execution logs
[2024-06-21T01:13:47.494+0000] {taskinstance.py:2905} ERROR - Task failed with exception
Traceback (most recent call last):
  File "/home/airflow/.local/lib/python3.12/site-packages/airflow/models/taskinstance.py", line 465, in _execute_task
    result = _execute_callable(context=context, **execute_callable_kwargs)
             ^^^^^^^^^^^^^^^^^^^^^^^^^^^^^^^^^^^^^^^^^^^^^^^^^^^^^^^^^^^^^
  File "/home/airflow/.local/lib/python3.12/site-packages/airflow/models/taskinstance.py", line 432, in _execute_callable
    return execute_callable(context=context, **execute_callable_kwargs)
           ^^^^^^^^^^^^^^^^^^^^^^^^^^^^^^^^^^^^^^^^^^^^^^^^^^^^^^^^^^^^
  File "/home/airflow/.local/lib/python3.12/site-packages/airflow/models/baseoperator.py", line 400, in wrapper
    return func(self, *args, **kwargs)
           ^^^^^^^^^^^^^^^^^^^^^^^^^^^
  File "/home/airflow/.local/lib/python3.12/site-packages/airflow/decorators/base.py", line 265, in execute
    return_value = super().execute(context)
                   ^^^^^^^^^^^^^^^^^^^^^^^^
  File "/home/airflow/.local/lib/python3.12/site-packages/airflow/models/baseoperator.py", line 400, in wrapper
    return func(self, *args, **kwargs)
           ^^^^^^^^^^^^^^^^^^^^^^^^^^^
  File "/home/airflow/.local/lib/python3.12/site-packages/airflow/operators/python.py", line 437, in execute
    return super().execute(context=serializable_context)
           ^^^^^^^^^^^^^^^^^^^^^^^^^^^^^^^^^^^^^^^^^^^^^
  File "/home/airflow/.local/lib/python3.12/site-packages/airflow/models/baseoperator.py", line 400, in wrapper
    return func(self, *args, **kwargs)
           ^^^^^^^^^^^^^^^^^^^^^^^^^^^
  File "/home/airflow/.local/lib/python3.12/site-packages/airflow/operators/python.py", line 235, in execute
    return_value = self.execute_callable()
                   ^^^^^^^^^^^^^^^^^^^^^^^
  File "/home/airflow/.local/lib/python3.12/site-packages/airflow/operators/python.py", line 759, in execute_callable
    result = self._execute_python_callable_in_subprocess(python_path)
             ^^^^^^^^^^^^^^^^^^^^^^^^^^^^^^^^^^^^^^^^^^^^^^^^^^^^^^^^
  File "/home/airflow/.local/lib/python3.12/site-packages/airflow/operators/python.py", line 514, in _execute_python_callable_in_subprocess
    raise AirflowException(error_msg) from None
airflow.exceptions.AirflowException: Process returned non-zero exit status 1.
name 'time' is not defined
[2024-06-21T01:13:47.498+0000] {taskinstance.py:1206} INFO - Marking task as FAILED. dag_id=pokemons, task_id=getpokemons, run_id=manual__2024-06-21T01:13:37.153672+00:00, execution_date=20240621T011337, start_date=20240621T011338, end_date=20240621T011347
[2024-06-21T01:13:47.524+0000] {standard_task_runner.py:110} ERROR - Failed to execute job 58 for task getpokemons (Process returned non-zero exit status 1.
name 'time' is not defined; 656)
[2024-06-21T01:13:47.539+0000] {local_task_job_runner.py:240} INFO - Task exited with return code 1
[2024-06-21T01:13:47.558+0000] {taskinstance.py:3498} INFO - 0 downstream tasks scheduled from follow-on schedule check
[2024-06-21T01:13:47.563+0000] {local_task_job_runner.py:222} INFO - ::endgroup::
